<sdf version='1.10'>
  <world name='empty'>
    <physics name='1ms' type='ignored'>
      <max_step_size>0.001</max_step_size>
      <real_time_factor>1</real_time_factor>
      <real_time_update_rate>1000</real_time_update_rate>
    </physics>
    <plugin name='gz::sim::systems::Physics' filename='gz-sim-physics-system'/>
    <plugin name='gz::sim::systems::UserCommands' filename='gz-sim-user-commands-system'/>
    <plugin name='gz::sim::systems::SceneBroadcaster' filename='gz-sim-scene-broadcaster-system'/>
    <plugin name='gz::sim::systems::Sensors' filename='gz-sim-sensors-system'>
      <render_engine>ogre2</render_engine>
    </plugin>
    <plugin name='gz::sim::systems::Contact' filename='gz-sim-contact-system'/>
    <gravity>0 0 -9.8000000000000007</gravity>
    <magnetic_field>5.5644999999999998e-06 2.2875799999999999e-05 -4.2388400000000002e-05</magnetic_field>
    <atmosphere type='adiabatic'/>
    <scene>
      <ambient>0.400000006 0.400000006 0.400000006 1</ambient>
      <background>0.699999988 0.699999988 0.699999988 1</background>
      <shadows>true</shadows>
    </scene>
    <model name='ground_plane'>
      <static>true</static>
      <link name='link'>
        <collision name='collision'>
          <geometry>
            <plane>
              <normal>0 0 1</normal>
              <size>100 100</size>
            </plane>
          </geometry>
          <surface>
            <friction>
              <ode/>
            </friction>
            <bounce/>
            <contact/>
          </surface>
        </collision>
        <visual name='visual'>
          <geometry>
            <plane>
              <normal>0 0 1</normal>
              <size>100 100</size>
            </plane>
          </geometry>
          <material>
            <ambient>0.800000012 0.800000012 0.800000012 1</ambient>
            <diffuse>0.800000012 0.800000012 0.800000012 1</diffuse>
            <specular>0.800000012 0.800000012 0.800000012 1</specular>
          </material>
        </visual>
        <pose>0 0 0 0 0 0</pose>
        <inertial>
          <pose>0 0 0 0 0 0</pose>
          <mass>1</mass>
          <inertia>
            <ixx>1</ixx>
            <ixy>0</ixy>
            <ixz>0</ixz>
            <iyy>1</iyy>
            <iyz>0</iyz>
            <izz>1</izz>
          </inertia>
        </inertial>
        <enable_wind>false</enable_wind>
      </link>
      <pose>0 0 0 0 0 0</pose>
      <self_collide>false</self_collide>
    </model>
    <model name='sucata'>
      <link name='base_link'>
        <inertial>
          <pose>0.02178571428571429 0 0.062857142857142861 0 0 0</pose>
          <mass>0.69999999999999996</mass>
          <inertia>
            <ixx>0.0025861607142857149</ixx>
            <ixy>0</ixy>
            <ixz>-0.00041142857142857159</ixz>
            <iyy>0.0045462202380952381</iyy>
            <iyz>0</iyz>
            <izz>0.0046038095238095239</izz>
          </inertia>
        </inertial>
        <collision name='base_link_collision'>
          <pose>0 0 0.050000000000000003 0 0 0</pose>
          <geometry>
            <box>
              <size>0.20499999999999999 0.13500000000000001 0.10000000000000001</size>
            </box>
          </geometry>
          <surface>
            <friction>
              <ode/>
            </friction>
            <bounce/>
            <contact/>
          </surface>
        </collision>
        <collision name='base_link_fixed_joint_lump__lidar_collision_1'>
          <pose>0.050000000000000003 0 0.11 0 0 0</pose>
          <geometry>
            <cylinder>
              <length>0.02</length>
              <radius>0.025000000000000001</radius>
            </cylinder>
          </geometry>
          <surface>
            <contact>
              <ode/>
            </contact>
            <friction>
              <ode/>
            </friction>
            <bounce/>
          </surface>
        </collision>
        <visual name='base_link_visual'>
          <pose>0 0 0.050000000000000003 0 0 0</pose>
          <geometry>
            <box>
              <size>0.20499999999999999 0.13500000000000001 0.10000000000000001</size>
            </box>
          </geometry>
          <material>
            <diffuse>0 0.75000006 0 1</diffuse>
            <ambient>0 0.75000006 0 1</ambient>
          </material>
        </visual>
        <visual name='base_link_fixed_joint_lump__camera_link_visual_1'>
          <pose>0.10249999999999999 0 0.080000000000000002 0 0 0</pose>
          <geometry>
            <box>
              <size>0.01 0.029999999999999999 0.029999999999999999</size>
            </box>
          </geometry>
          <material>
            <script>
              <name>Gazebo/Red</name>
              <uri>file://media/materials/scripts/gazebo.material</uri>
            </script>
          </material>
        </visual>
        <visual name='base_link_fixed_joint_lump__lidar_visual_2'>
          <pose>0.050000000000000003 0 0.11 0 0 0</pose>
          <geometry>
            <cylinder>
              <length>0.02</length>
              <radius>0.025000000000000001</radius>
            </cylinder>
          </geometry>
          <material>
            <script>
              <name>Gazebo/Black</name>
              <uri>file://media/materials/scripts/gazebo.material</uri>
            </script>
            <diffuse>0.875 0.875 0.875 1</diffuse>
            <ambient>0.875 0.875 0.875 1</ambient>
          </material>
        </visual>
        <sensor name='camera' type='camera'>
          <pose>0.10249999999999999 0 0.080000000000000002 0 0 0</pose>
          <topic>camera/image_raw</topic>
          <update_rate>10</update_rate>
          <enable_metrics>false</enable_metrics>
          <camera name='__default__'>
            <pose>0 0 0 0 0 0</pose>
            <horizontal_fov>1.089</horizontal_fov>
            <image>
              <width>640</width>
              <height>480</height>
              <format>RGB_INT8</format>
              <anti_aliasing>4</anti_aliasing>
            </image>
            <camera_info_topic>__default__</camera_info_topic>
            <trigger_topic></trigger_topic>
            <triggered>false</triggered>
            <clip>
              <near>0.050000000000000003</near>
              <far>8</far>
            </clip>
            <save enabled='false'>
              <path>__default__</path>
            </save>
            <visibility_mask>4294967295</visibility_mask>
            <noise>
              <type>none</type>
              <mean>0</mean>
              <stddev>0</stddev>
            </noise>
            <distortion>
              <k1>0</k1>
              <k2>0</k2>
              <k3>0</k3>
              <p1>0</p1>
              <p2>0</p2>
              <center>0.5 0.5</center>
            </distortion>
            <lens>
              <type>stereographic</type>
              <scale_to_hfov>true</scale_to_hfov>
              <cutoff_angle>1.5707963267948966</cutoff_angle>
              <env_texture_size>256</env_texture_size>
            </lens>
            <optical_frame_id></optical_frame_id>
          </camera>
        </sensor>
        <sensor name='laser' type='gpu_lidar'>
          <pose>0.050000000000000003 0 0.11 0 0 0</pose>
          <topic>scan</topic>
          <update_rate>10</update_rate>
          <enable_metrics>false</enable_metrics>
          <lidar>
            <scan>
              <horizontal>
                <samples>360</samples>
                <resolution>1</resolution>
                <min_angle>-3.1400000000000001</min_angle>
                <max_angle>3.1400000000000001</max_angle>
              </horizontal>
              <vertical>
                <samples>1</samples>
                <min_angle>0</min_angle>
                <max_angle>0</max_angle>
                <resolution>1</resolution>
              </vertical>
            </scan>
            <range>
              <min>0.29999999999999999</min>
              <max>12</max>
              <resolution>0</resolution>
            </range>
            <noise>
              <type>none</type>
              <mean>0</mean>
              <stddev>0</stddev>
            </noise>
            <visibility_mask>4294967295</visibility_mask>
          </lidar>
        </sensor>
        <pose>0 0 0 0 0 0</pose>
        <enable_wind>false</enable_wind>
      </link>
      <joint name='base_left_front_wheel_joint' type='revolute'>
        <pose>0 0 0 0 0 0</pose>
        <parent>base_link</parent>
        <child>left_front_wheel</child>
        <axis>
          <xyz>0 1 0</xyz>
          <limit>
            <lower>-inf</lower>
            <upper>inf</upper>
            <effort>inf</effort>
            <velocity>inf</velocity>
            <stiffness>100000000</stiffness>
            <dissipation>1</dissipation>
          </limit>
          <dynamics>
            <spring_reference>0</spring_reference>
            <spring_stiffness>0</spring_stiffness>
            <damping>0</damping>
            <friction>0</friction>
          </dynamics>
        </axis>
      </joint>
      <link name='left_front_wheel'>
        <pose>0.080000000000000002 0.085000000000000034 0.015000000000000003 -2.427846613021677e-30 5.1316613820510416e-17 -6.2294433527933798e-47</pose>
        <inertial>
          <pose>0 0 0 0 0 0</pose>
          <mass>0.10000000000000001</mass>
          <inertia>
            <ixx>6.0833333333333339e-05</ixx>
            <ixy>0</ixy>
            <ixz>0</ixz>
            <iyy>6.0833333333333339e-05</iyy>
            <iyz>0</iyz>
            <izz>0.00010124999999999999</izz>
          </inertia>
        </inertial>
        <collision name='left_front_wheel_collision'>
          <pose>0 0 0 1.5700000000000001 0 0</pose>
          <geometry>
            <cylinder>
              <length>0.035000000000000003</length>
              <radius>0.044999999999999998</radius>
            </cylinder>
          </geometry>
          <surface>
            <friction>
              <ode/>
            </friction>
            <bounce/>
            <contact/>
          </surface>
        </collision>
        <visual name='left_front_wheel_visual'>
          <pose>0 0 0 1.5700000000000001 0 0</pose>
          <geometry>
            <cylinder>
              <length>0.035000000000000003</length>
              <radius>0.044999999999999998</radius>
            </cylinder>
          </geometry>
          <material>
            <diffuse>0.875 0.875 0.875 1</diffuse>
            <ambient>0.875 0.875 0.875 1</ambient>
          </material>
        </visual>
        <enable_wind>false</enable_wind>
      </link>
      <joint name='base_left_rear_wheel_joint' type='revolute'>
        <pose>0 0 0 0 0 0</pose>
        <parent>base_link</parent>
        <child>left_rear_wheel</child>
        <axis>
          <xyz>0 1 0</xyz>
          <limit>
            <lower>-inf</lower>
            <upper>inf</upper>
            <effort>inf</effort>
            <velocity>inf</velocity>
            <stiffness>100000000</stiffness>
            <dissipation>1</dissipation>
          </limit>
          <dynamics>
            <spring_reference>0</spring_reference>
            <spring_stiffness>0</spring_stiffness>
            <damping>0</damping>
            <friction>0</friction>
          </dynamics>
        </axis>
      </joint>
      <link name='left_rear_wheel'>
        <pose>-0.080000000000000002 0.085000000000000006 0.015000000000000003 -2.4026981809197334e-30 5.078506094143894e-17 -1.2621774483536189e-29</pose>
        <inertial>
          <pose>0 0 0 0 0 0</pose>
          <mass>0.10000000000000001</mass>
          <inertia>
            <ixx>6.0833333333333339e-05</ixx>
            <ixy>0</ixy>
            <ixz>0</ixz>
            <iyy>6.0833333333333339e-05</iyy>
            <iyz>0</iyz>
            <izz>0.00010124999999999999</izz>
          </inertia>
        </inertial>
        <collision name='left_rear_wheel_collision'>
          <pose>0 0 0 1.5700000000000001 0 0</pose>
          <geometry>
            <cylinder>
              <length>0.035000000000000003</length>
              <radius>0.044999999999999998</radius>
            </cylinder>
          </geometry>
          <surface>
            <friction>
              <ode/>
            </friction>
            <bounce/>
            <contact/>
          </surface>
        </collision>
        <visual name='left_rear_wheel_visual'>
          <pose>0 0 0 1.5700000000000001 0 0</pose>
          <geometry>
            <cylinder>
              <length>0.035000000000000003</length>
              <radius>0.044999999999999998</radius>
            </cylinder>
          </geometry>
          <material>
            <diffuse>0.875 0.875 0.875 1</diffuse>
            <ambient>0.875 0.875 0.875 1</ambient>
          </material>
        </visual>
        <enable_wind>false</enable_wind>
      </link>
      <joint name='base_right_front_wheel_joint' type='revolute'>
        <pose>0 0 0 0 0 0</pose>
        <parent>base_link</parent>
        <child>right_front_wheel</child>
        <axis>
          <xyz>0 1 0</xyz>
          <limit>
            <lower>-inf</lower>
            <upper>inf</upper>
            <effort>inf</effort>
            <velocity>inf</velocity>
            <stiffness>100000000</stiffness>
            <dissipation>1</dissipation>
          </limit>
          <dynamics>
            <spring_reference>0</spring_reference>
            <spring_stiffness>0</spring_stiffness>
            <damping>0</damping>
            <friction>0</friction>
          </dynamics>
        </axis>
      </joint>
      <link name='right_front_wheel'>
        <pose>0.080000000000000002 -0.084999999999999978 0.015000000000000003 2.6110073467498549e-30 -5.5188023528573401e-17 -1.2621774483536189e-29</pose>
        <inertial>
          <pose>0 0 0 0 0 0</pose>
          <mass>0.10000000000000001</mass>
          <inertia>
            <ixx>6.0833333333333339e-05</ixx>
            <ixy>0</ixy>
            <ixz>0</ixz>
            <iyy>6.0833333333333339e-05</iyy>
            <iyz>0</iyz>
            <izz>0.00010124999999999999</izz>
          </inertia>
        </inertial>
        <collision name='right_front_wheel_collision'>
          <pose>0 0 0 1.5700000000000001 0 0</pose>
          <geometry>
            <cylinder>
              <length>0.035000000000000003</length>
              <radius>0.044999999999999998</radius>
            </cylinder>
          </geometry>
          <surface>
            <friction>
              <ode/>
            </friction>
            <bounce/>
            <contact/>
          </surface>
        </collision>
        <visual name='right_front_wheel_visual'>
          <pose>0 0 0 1.5700000000000001 0 0</pose>
          <geometry>
            <cylinder>
              <length>0.035000000000000003</length>
              <radius>0.044999999999999998</radius>
            </cylinder>
          </geometry>
          <material>
            <diffuse>0.875 0.875 0.875 1</diffuse>
            <ambient>0.875 0.875 0.875 1</ambient>
          </material>
        </visual>
        <enable_wind>false</enable_wind>
      </link>
      <joint name='base_right_rear_wheel_joint' type='revolute'>
        <pose>0 0 0 0 0 0</pose>
        <parent>base_link</parent>
        <child>right_rear_wheel</child>
        <axis>
          <xyz>0 1 0</xyz>
          <limit>
            <lower>-inf</lower>
            <upper>inf</upper>
            <effort>inf</effort>
            <velocity>inf</velocity>
            <stiffness>100000000</stiffness>
            <dissipation>1</dissipation>
          </limit>
          <dynamics>
            <spring_reference>0</spring_reference>
            <spring_stiffness>0</spring_stiffness>
            <damping>0</damping>
            <friction>0</friction>
          </dynamics>
        </axis>
      </joint>
      <link name='right_rear_wheel'>
        <pose>-0.080000000000000002 -0.085000000000000006 0.015000000000000003 2.5319605708519733e-30 -5.351723697804388e-17 -6.7751766944674156e-47</pose>
        <inertial>
          <pose>0 0 0 0 0 0</pose>
          <mass>0.10000000000000001</mass>
          <inertia>
            <ixx>6.0833333333333339e-05</ixx>
            <ixy>0</ixy>
            <ixz>0</ixz>
            <iyy>6.0833333333333339e-05</iyy>
            <iyz>0</iyz>
            <izz>0.00010124999999999999</izz>
          </inertia>
        </inertial>
        <collision name='right_rear_wheel_collision'>
          <pose>0 0 0 1.5700000000000001 0 0</pose>
          <geometry>
            <cylinder>
              <length>0.035000000000000003</length>
              <radius>0.044999999999999998</radius>
            </cylinder>
          </geometry>
          <surface>
            <friction>
              <ode/>
            </friction>
            <bounce/>
            <contact/>
          </surface>
        </collision>
        <visual name='right_rear_wheel_visual'>
          <pose>0 0 0 1.5700000000000001 0 0</pose>
          <geometry>
            <cylinder>
              <length>0.035000000000000003</length>
              <radius>0.044999999999999998</radius>
            </cylinder>
          </geometry>
          <material>
            <diffuse>0.875 0.875 0.875 1</diffuse>
            <ambient>0.875 0.875 0.875 1</ambient>
          </material>
        </visual>
        <enable_wind>false</enable_wind>
      </link>
      <plugin name='gz_ros2_control::GazeboSimROS2ControlPlugin' filename='libgz_ros2_control-system.so'>
        <parameters>/home/guilassas24/ros2_ws/install/sucata/share/sucata/config/my_controller.yaml</parameters>
        <controller_manager_name>controller_manager</controller_manager_name>
      </plugin>
      <frame name='base_footprint_joint' attached_to='base_link'>
        <pose>0 0 0 0 0 0</pose>
      </frame>
      <frame name='base_footprint' attached_to='base_footprint_joint'>
        <pose>0 0 0 0 0 0</pose>
      </frame>
      <frame name='camera_optical_joint' attached_to='camera_link'>
        <pose>0 0 0 -1.5707963267948959 -5.5511151231257827e-17 -1.5707963267948959</pose>
      </frame>
      <frame name='camera_link_optical' attached_to='camera_optical_joint'>
        <pose>0 0 0 0 0 0</pose>
      </frame>
      <frame name='camera_joint' attached_to='base_link'>
        <pose>0.10249999999999999 0 0.080000000000000002 0 0 0</pose>
      </frame>
      <frame name='camera_link' attached_to='camera_joint'>
        <pose>0 0 0 0 0 0</pose>
      </frame>
      <frame name='lidar_joint' attached_to='base_link'>
        <pose>0.050000000000000003 0 0.11 0 0 0</pose>
      </frame>
      <frame name='lidar' attached_to='lidar_joint'>
        <pose>0 0 0 0 0 0</pose>
      </frame>
      <pose>2.1621211302144775e-10 -1.1306174464690826e-10 0.030013086224853991 3.7669618228831833e-09 7.2224816490373716e-09 -9.4595038052460619e-14</pose>
      <static>false</static>
      <self_collide>false</self_collide>
    </model>
    <model name='box'>
      <pose>1.7509439024574167 1.2493411962078598 0.49999999990199806 6.2287739151293738e-22 9.3279666454713669e-22 -3.6315533669320137e-22</pose>
      <link name='box_link'>
        <inertial>
          <inertia>
            <ixx>0.16666</ixx>
            <ixy>0</ixy>
            <ixz>0</ixz>
            <iyy>0.16666</iyy>
            <iyz>0</iyz>
            <izz>0.16666</izz>
          </inertia>
          <mass>1</mass>
          <pose>0 0 0 0 0 0</pose>
        </inertial>
        <collision name='box_collision'>
          <geometry>
            <box>
              <size>1 1 1</size>
            </box>
          </geometry>
          <surface>
            <friction>
              <ode/>
            </friction>
            <bounce/>
            <contact/>
          </surface>
        </collision>
        <visual name='box_visual'>
          <geometry>
            <box>
              <size>1 1 1</size>
            </box>
          </geometry>
          <material>
            <ambient>0.300000012 0.300000012 0.300000012 1</ambient>
            <diffuse>0.699999988 0.699999988 0.699999988 1</diffuse>
            <specular>1 1 1 1</specular>
          </material>
        </visual>
        <pose>0 0 0 0 0 0</pose>
        <enable_wind>false</enable_wind>
      </link>
      <static>false</static>
      <self_collide>false</self_collide>
    </model>
    <model name='cone'>
      <pose>-1.7889992545019626 0.26015043447266883 0.49999999993296756 5.2541471503228405e-17 -7.7132841033694056e-10 -2.8937183272912105e-22</pose>
      <link name='cone_link'>
        <inertial>
          <inertia>
            <ixx>0.074999999999999997</ixx>
            <ixy>0</ixy>
            <ixz>0</ixz>
            <iyy>0.074999999999999997</iyy>
            <iyz>0</iyz>
            <izz>0.074999999999999997</izz>
          </inertia>
          <mass>1</mass>
          <pose>0 0 0 0 0 0</pose>
        </inertial>
        <collision name='cone_collision'>
          <geometry>
            <cone>
              <radius>0.5</radius>
              <length>1</length>
            </cone>
          </geometry>
          <surface>
            <friction>
              <ode/>
            </friction>
            <bounce/>
            <contact/>
          </surface>
        </collision>
        <visual name='cone_visual'>
          <geometry>
            <cone>
              <radius>0.5</radius>
              <length>1</length>
            </cone>
          </geometry>
          <material>
            <ambient>0.300000012 0.300000012 0.300000012 1</ambient>
            <diffuse>0.699999988 0.699999988 0.699999988 1</diffuse>
            <specular>1 1 1 1</specular>
          </material>
        </visual>
        <pose>0 0 0 0 0 0</pose>
        <enable_wind>false</enable_wind>
      </link>
      <static>false</static>
      <self_collide>false</self_collide>
    </model>
    <model name='cylinder'>
      <pose>1.3375298649124936 -1.9400935388867615 0.49999942638036005 -4.3361760871588193e-20 6.09388325266005e-19 2.1052028277643034e-21</pose>
      <link name='cylinder_link'>
        <inertial>
          <inertia>
            <ixx>0.14580000000000001</ixx>
            <ixy>0</ixy>
            <ixz>0</ixz>
            <iyy>0.14580000000000001</iyy>
            <iyz>0</iyz>
            <izz>0.125</izz>
          </inertia>
          <mass>1</mass>
          <pose>0 0 0 0 0 0</pose>
        </inertial>
        <collision name='cylinder_collision'>
          <geometry>
            <cylinder>
              <radius>0.5</radius>
              <length>1</length>
            </cylinder>
          </geometry>
          <surface>
            <friction>
              <ode/>
            </friction>
            <bounce/>
            <contact/>
          </surface>
        </collision>
        <visual name='cylinder_visual'>
          <geometry>
            <cylinder>
              <radius>0.5</radius>
              <length>1</length>
            </cylinder>
          </geometry>
          <material>
            <ambient>0.300000012 0.300000012 0.300000012 1</ambient>
            <diffuse>0.699999988 0.699999988 0.699999988 1</diffuse>
            <specular>1 1 1 1</specular>
          </material>
        </visual>
        <pose>0 0 0 0 0 0</pose>
        <enable_wind>false</enable_wind>
      </link>
      <static>false</static>
      <self_collide>false</self_collide>
    </model>
    <light name='sun' type='directional'>
      <pose>0 0 10 0 0 0</pose>
      <cast_shadows>true</cast_shadows>
      <intensity>1</intensity>
      <direction>-0.5 0.10000000000000001 -0.90000000000000002</direction>
      <diffuse>0.800000012 0.800000012 0.800000012 1</diffuse>
      <specular>0.200000003 0.200000003 0.200000003 1</specular>
      <attenuation>
        <range>1000</range>
        <linear>0.01</linear>
        <constant>0.90000000000000002</constant>
        <quadratic>0.001</quadratic>
      </attenuation>
      <spot>
        <inner_angle>0</inner_angle>
        <outer_angle>0</outer_angle>
        <falloff>0</falloff>
      </spot>
    </light>
  </world>
</sdf>
